2025-02-17 23:08:40,550 - INFO - Logging initialized
2025-02-17 23:08:40,550 - INFO - Starting analysis
2025-02-17 23:08:40,550 - INFO - Loaded existing category summary
2025-02-17 23:08:40,550 - INFO - Found existing analysis results
2025-02-17 23:08:40,550 - INFO - Category Distribution for Qualified Projects:
2025-02-17 23:08:40,550 - INFO -   Infrastructure: 40
2025-02-17 23:08:40,550 - INFO -   DeFi: 37
2025-02-17 23:08:40,550 - INFO -   Gaming: 15
2025-02-17 23:08:40,550 - INFO -   Other: 10
2025-02-17 23:08:40,550 - INFO -   NFT: 9
2025-02-17 23:08:40,550 - INFO -   Social: 8
2025-02-17 23:08:40,550 - INFO - Creating visualizations
2025-02-17 23:08:40,670 - INFO - Saved category distribution plot
2025-02-17 23:08:40,677 - ERROR - Error creating visualizations: Could not interpret value `confidence` for `y`. An entry with this name does not appear in `data`.
Traceback (most recent call last):
  File "/Users/jnaulty/github/sui-ai-agent-typhoon-hackathon/tooling/data-hackathon/analyze_description.py", line 107, in create_visualizations
    sns.boxplot(data=df, x='category', y='confidence')
    ~~~~~~~~~~~^^^^^^^^^^^^^^^^^^^^^^^^^^^^^^^^^^^^^^^
  File "/Users/jnaulty/github/sui-ai-agent-typhoon-hackathon/tooling/data-hackathon/venv/lib/python3.13/site-packages/seaborn/categorical.py", line 1597, in boxplot
    p = _CategoricalPlotter(
        data=data,
    ...<4 lines>...
        legend=legend,
    )
  File "/Users/jnaulty/github/sui-ai-agent-typhoon-hackathon/tooling/data-hackathon/venv/lib/python3.13/site-packages/seaborn/categorical.py", line 67, in __init__
    super().__init__(data=data, variables=variables)
    ~~~~~~~~~~~~~~~~^^^^^^^^^^^^^^^^^^^^^^^^^^^^^^^^
  File "/Users/jnaulty/github/sui-ai-agent-typhoon-hackathon/tooling/data-hackathon/venv/lib/python3.13/site-packages/seaborn/_base.py", line 634, in __init__
    self.assign_variables(data, variables)
    ~~~~~~~~~~~~~~~~~~~~~^^^^^^^^^^^^^^^^^
  File "/Users/jnaulty/github/sui-ai-agent-typhoon-hackathon/tooling/data-hackathon/venv/lib/python3.13/site-packages/seaborn/_base.py", line 679, in assign_variables
    plot_data = PlotData(data, variables)
  File "/Users/jnaulty/github/sui-ai-agent-typhoon-hackathon/tooling/data-hackathon/venv/lib/python3.13/site-packages/seaborn/_core/data.py", line 58, in __init__
    frame, names, ids = self._assign_variables(data, variables)
                        ~~~~~~~~~~~~~~~~~~~~~~^^^^^^^^^^^^^^^^^
  File "/Users/jnaulty/github/sui-ai-agent-typhoon-hackathon/tooling/data-hackathon/venv/lib/python3.13/site-packages/seaborn/_core/data.py", line 232, in _assign_variables
    raise ValueError(err)
ValueError: Could not interpret value `confidence` for `y`. An entry with this name does not appear in `data`.
2025-02-17 23:08:40,678 - INFO - Created visualizations from existing data
